Workbook

Sheet START HERE
A2: BUS 331 — Phase 2: Security Analysis & Selection
A3: Student Template | Endicott College | Institutional Portfolio Management Project
B5: Overview
B6: This workbook has seven tabs: START HERE, SUMMARY, Client 1, Client 2, Client 3, ISSUER CHECK, and EVIDENCE LOG. Complete one client tab per assigned client, the required Issuer Reality Check rows, and one FactSet retrieval record for each recommendation and material portfolio-risk input.
B8: Before You Start — Complete Phase 1 First
B9: Your Phase 1 market view, client IPS, unresolved information gaps, and downstream guardrails must be approved before security research begins. Every candidate and Issuer Reality Check must trace to that mandate; the macro filter on each client tab must pass before selection.
B11: Section 1 — Security Selection Table
B12: Enter at least 10 securities per client (add rows as needed by copying an existing row). Weights in column G must sum to 100% — the total row turns green when correct. Column J (Macro Filter) must be YES for every holding. Link each security to a thesis number in column K.
B14: Section 2 — Derivative Hedge Summary
B15: Every client needs at least one derivative hedge (e.g. Protective Put). Document the chosen strategy in full — cost, strike, expiration, and net Bear Case impact. Then complete the alternative comparison table for at least one other strategy you considered and explain why you rejected it.
B17: Section 3 — Investment Thesis Log
B18: Complete one thesis block per security. Number must match column K in Section 1. Each block requires: macro connection, investment rationale, data citation, IPS suitability check, and an AI audit note if AI was used. Five blocks are pre-built; copy to add more.
B20: AI Audit Log Reminder
B21: Any AI tool used to suggest securities, expected returns, or hedge parameters must be documented in your team's AI Audit Log. The Hallucination Clause applies: unverified AI data = professional negligence. Every number must trace to FactSet, FRED, or SEC.
... B41: ☐ Final work and required licensed-source evidence prepared for private Canvas submission; nothing placed in the public repository

Sheet SUMMARY
A2: Phase 2 Security Selection Summary — All Clients
A3: Auto-linked from Client 1, 2, 3 tabs | Green = weights correct | Red = recheck
A4: This summary pulls key stats from each client tab. Verify all three weight totals are green (100%) and all portfolio betas are within the expected range for each client's risk profile before submitting.
B6: Metric | D6: Client 1 | F6: Client 2 | H6: Client 3
B7: Total Weight | D7: ='Client 1'!G22 -> 0 | F7: ='Client 2'!G22 -> 0 | H7: ='Client 3'!G22 -> 0
B8: Total $ Invested | D8: ='Client 1'!H22 -> 0 | F8: ='Client 2'!H22 -> 0 | H8: ='Client 3'!H22 -> 0
B9: Portfolio Beta (wtd) | D9: ='Client 1'!I22 | F9: ='Client 2'!I22 | H9: ='Client 3'!I22
B10: IPS Return Target | D10: ='Client 1'!G5 -> 0 | F10: ='Client 2'!G5 -> 0 | H10: ='Client 3'!G5 -> 0
B11: IPS Max σ | D11: ='Client 1'!I5 -> 0 | F11: ='Client 2'!I5 -> 0 | H11: ='Client 3'!I5 -> 0

Sheet Client 1
A2: Phase 2 — Security Analysis & Selection | Client 1
A3: BUS 331 Investments | Endicott College | Phase 2: Security Analysis & Selection
B5: Client Name / ID: | F5: IPS Return Target: | H5: IPS Max σ: | J5: Macro Regime:
A7: ⚠ MACRO FILTER (Phase 1 required): Every security below must survive your Phase 1 macro thesis. If your Base Case avoids a sector, you cannot hold it. Column J must be 'YES' for every row. Red = fails filter. Fix or remove the position.
A9: SECTION 1 — SECURITY SELECTION TABLE
A10: Enter one security per row. Blue text = student input. Weights (column G) must sum to 100% — watch the live total in row below the table. Add rows as needed; the weight total formula auto-adjusts.
B11: # | C11: Ticker | D11: Security / ETF Name | E11: Asset Class | F11: Sector | G11: Weight (%) | H11: $ Amount (of $500K) | I11: Beta (Est.) | J11: Macro Filter ✓ | K11: Thesis Ref # | L11: Data Source (FactSet / FRED / SEC)
B12: =1 -> 1 | H12: =IF(G12<>"",G12*500000,"")
B13: =2 -> 2 | H13: =IF(G13<>"",G13*500000,"")
B14: =3 -> 3 | H14: =IF(G14<>"",G14*500000,"")
B15: =4 -> 4 | H15: =IF(G15<>"",G15*500000,"")
B16: =5 -> 5 | H16: =IF(G16<>"",G16*500000,"")
B17: =6 -> 6 | H17: =IF(G17<>"",G17*500000,"")
B18: =7 -> 7 | H18: =IF(G18<>"",G18*500000,"")
B19: =8 -> 8 | H19: =IF(G19<>"",G19*500000,"")
B20: =9 -> 9 | H20: =IF(G20<>"",G20*500000,"")
B21: =10 -> 10 | H21: =IF(G21<>"",G21*500000,"")
A22: TOTAL WEIGHT (must equal 100%) | G22: =IFERROR(SUM(G12:G21),0) -> 0 | H22: =IFERROR(SUMIF(G12:G21,"<>",H12:H21),0) -> 0 | I22: {=IFERROR(SUMPRODUCT((G12:G21)*IF(ISNUMBER(_xlfn.SINGLE(I12:I21)),I12:I21,0))/IFERROR(SUM(G12:G21),1),"")} | J22: Portfolio β (wtd. avg) | K22: ← Green = weights sum to 100% Red = recheck weights
A25: SECTION 2 — DERIVATIVE HEDGE SUMMARY
A26: Mandatory: every client portfolio must include at least one derivative hedge strategy. Document the chosen hedge and compare it to at least one alternative. Source pricing from FactSet options screen or current market data.
B27: Hedge Strategy Chosen | J27: e.g. E.g. Protective Put on SPY — provides downside floor on equity sleeve
B28: Underlying Security / ETF | J28: e.g. E.g. SPY (SPDR S&P 500 ETF)
B29: Contract Type | J29: e.g. E.g. Put Option
B30: Strike Price | J30: e.g. E.g. $480 (≈5% OTM)
B31: Expiration / Duration | J31: e.g. E.g. 12-month expiration (Dec 2026)
B32: Option Premium / Cost | J32: e.g. E.g. $12.50 per share × 100 contracts = $125,000
B33: % of Portfolio Cost | J33: e.g. E.g. 2.5% of $500,000 AUM
B34: Downside Protected To | J34: e.g. E.g. Portfolio loss floored at –8% in Bear Case
B35: Net Bear Case Return (hedged) | J35: e.g. E.g. –6.5% (vs. –14% unhedged)
B37: Alternative Hedge Comparison (required — compare to at least 1 alternative)
B38: Strategy | C38: Cost | F38: Max Downside Protected | H38: Trade-off vs. Chosen Hedge | K38: Why Rejected?
A42: SECTION 3 — INVESTMENT THESIS LOG
A43: Complete one thesis block per security. Thesis # must match column K in Section 1. Each thesis must: (1) identify the macro connection to Phase 1, (2) cite a verifiable data source, and (3) confirm IPS suitability for this client.
A44: Thesis #1
B45: Security (Ticker + Name)
B46: Asset Class / Sector
B47: Macro Connection
B48: Investment Rationale
B49: Data Source & Citation
B50: IPS Suitability
...

Sheet Client 2
A2: Phase 2 — Security Analysis & Selection | Client 2
A3: BUS 331 Investments | Endicott College | Phase 2: Security Analysis & Selection
B5: Client Name / ID: | F5: IPS Return Target: | H5: IPS Max σ: | J5: Macro Regime:
A7: ⚠ MACRO FILTER (Phase 1 required): Every security below must survive your Phase 1 macro thesis. If your Base Case avoids a sector, you cannot hold it. Column J must be 'YES' for every row. Red = fails filter. Fix or remove the position.
A9: SECTION 1 — SECURITY SELECTION TABLE
A10: Enter one security per row. Blue text = student input. Weights (column G) must sum to 100% — watch the live total in row below the table. Add rows as needed; the weight total formula auto-adjusts.
B11: # | C11: Ticker | D11: Security / ETF Name | E11: Asset Class | F11: Sector | G11: Weight (%) | H11: $ Amount (of $500K) | I11: Beta (Est.) | J11: Macro Filter ✓ | K11: Thesis Ref # | L11: Data Source (FactSet / FRED / SEC)
B12: =1 -> 1 | H12: =IF(G12<>"",G12*500000,"")
B13: =2 -> 2 | H13: =IF(G13<>"",G13*500000,"")
B14: =3 -> 3 | H14: =IF(G14<>"",G14*500000,"")
B15: =4 -> 4 | H15: =IF(G15<>"",G15*500000,"")
B16: =5 -> 5 | H16: =IF(G16<>"",G16*500000,"")
B17: =6 -> 6 | H17: =IF(G17<>"",G17*500000,"")
B18: =7 -> 7 | H18: =IF(G18<>"",G18*500000,"")
B19: =8 -> 8 | H19: =IF(G19<>"",G19*500000,"")
B20: =9 -> 9 | H20: =IF(G20<>"",G20*500000,"")
B21: =10 -> 10 | H21: =IF(G21<>"",G21*500000,"")
A22: TOTAL WEIGHT (must equal 100%) | G22: =IFERROR(SUM(G12:G21),0) -> 0 | H22: =IFERROR(SUMIF(G12:G21,"<>",H12:H21),0) -> 0 | I22: {=IFERROR(SUMPRODUCT((G12:G21)*IF(ISNUMBER(_xlfn.SINGLE(I12:I21)),I12:I21,0))/IFERROR(SUM(G12:G21),1),"")} | J22: Portfolio β (wtd. avg) | K22: ← Green = weights sum to 100% Red = recheck weights
A25: SECTION 2 — DERIVATIVE HEDGE SUMMARY
A26: Mandatory: every client portfolio must include at least one derivative hedge strategy. Document the chosen hedge and compare it to at least one alternative. Source pricing from FactSet options screen or current market data.
B27: Hedge Strategy Chosen | J27: e.g. E.g. Protective Put on SPY — provides downside floor on equity sleeve
B28: Underlying Security / ETF | J28: e.g. E.g. SPY (SPDR S&P 500 ETF)
B29: Contract Type | J29: e.g. E.g. Put Option
B30: Strike Price | J30: e.g. E.g. $480 (≈5% OTM)
B31: Expiration / Duration | J31: e.g. E.g. 12-month expiration (Dec 2026)
B32: Option Premium / Cost | J32: e.g. E.g. $12.50 per share × 100 contracts = $125,000
B33: % of Portfolio Cost | J33: e.g. E.g. 2.5% of $500,000 AUM
B34: Downside Protected To | J34: e.g. E.g. Portfolio loss floored at –8% in Bear Case
B35: Net Bear Case Return (hedged) | J35: e.g. E.g. –6.5% (vs. –14% unhedged)
B37: Alternative Hedge Comparison (required — compare to at least 1 alternative)
B38: Strategy | C38: Cost | F38: Max Downside Protected | H38: Trade-off vs. Chosen Hedge | K38: Why Rejected?
A42: SECTION 3 — INVESTMENT THESIS LOG
A43: Complete one thesis block per security. Thesis # must match column K in Section 1. Each thesis must: (1) identify the macro connection to Phase 1, (2) cite a verifiable data source, and (3) confirm IPS suitability for this client.
A44: Thesis #1
B45: Security (Ticker + Name)
B46: Asset Class / Sector
B47: Macro Connection
B48: Investment Rationale
B49: Data Source & Citation
B50: IPS Suitability
...

Sheet Client 3
A2: Phase 2 — Security Analysis & Selection | Client 3
A3: BUS 331 Investments | Endicott College | Phase 2: Security Analysis & Selection
B5: Client Name / ID: | F5: IPS Return Target: | H5: IPS Max σ: | J5: Macro Regime:
A7: ⚠ MACRO FILTER (Phase 1 required): Every security below must survive your Phase 1 macro thesis. If your Base Case avoids a sector, you cannot hold it. Column J must be 'YES' for every row. Red = fails filter. Fix or remove the position.
A9: SECTION 1 — SECURITY SELECTION TABLE
A10: Enter one security per row. Blue text = student input. Weights (column G) must sum to 100% — watch the live total in row below the table. Add rows as needed; the weight total formula auto-adjusts.
B11: # | C11: Ticker | D11: Security / ETF Name | E11: Asset Class | F11: Sector | G11: Weight (%) | H11: $ Amount (of $500K) | I11: Beta (Est.) | J11: Macro Filter ✓ | K11: Thesis Ref # | L11: Data Source (FactSet / FRED / SEC)
B12: =1 -> 1 | H12: =IF(G12<>"",G12*500000,"")
B13: =2 -> 2 | H13: =IF(G13<>"",G13*500000,"")
B14: =3 -> 3 | H14: =IF(G14<>"",G14*500000,"")
B15: =4 -> 4 | H15: =IF(G15<>"",G15*500000,"")
B16: =5 -> 5 | H16: =IF(G16<>"",G16*500000,"")
B17: =6 -> 6 | H17: =IF(G17<>"",G17*500000,"")
B18: =7 -> 7 | H18: =IF(G18<>"",G18*500000,"")
B19: =8 -> 8 | H19: =IF(G19<>"",G19*500000,"")
B20: =9 -> 9 | H20: =IF(G20<>"",G20*500000,"")
B21: =10 -> 10 | H21: =IF(G21<>"",G21*500000,"")
A22: TOTAL WEIGHT (must equal 100%) | G22: =IFERROR(SUM(G12:G21),0) -> 0 | H22: =IFERROR(SUMIF(G12:G21,"<>",H12:H21),0) -> 0 | I22: {=IFERROR(SUMPRODUCT((G12:G21)*IF(ISNUMBER(_xlfn.SINGLE(I12:I21)),I12:I21,0))/IFERROR(SUM(G12:G21),1),"")} | J22: Portfolio β (wtd. avg) | K22: ← Green = weights sum to 100% Red = recheck weights
A25: SECTION 2 — DERIVATIVE HEDGE SUMMARY
A26: Mandatory: every client portfolio must include at least one derivative hedge strategy. Document the chosen hedge and compare it to at least one alternative. Source pricing from FactSet options screen or current market data.
B27: Hedge Strategy Chosen | J27: e.g. E.g. Protective Put on SPY — provides downside floor on equity sleeve
B28: Underlying Security / ETF | J28: e.g. E.g. SPY (SPDR S&P 500 ETF)
B29: Contract Type | J29: e.g. E.g. Put Option
B30: Strike Price | J30: e.g. E.g. $480 (≈5% OTM)
B31: Expiration / Duration | J31: e.g. E.g. 12-month expiration (Dec 2026)
B32: Option Premium / Cost | J32: e.g. E.g. $12.50 per share × 100 contracts = $125,000
B33: % of Portfolio Cost | J33: e.g. E.g. 2.5% of $500,000 AUM
B34: Downside Protected To | J34: e.g. E.g. Portfolio loss floored at –8% in Bear Case
B35: Net Bear Case Return (hedged) | J35: e.g. E.g. –6.5% (vs. –14% unhedged)
B37: Alternative Hedge Comparison (required — compare to at least 1 alternative)
B38: Strategy | C38: Cost | F38: Max Downside Protected | H38: Trade-off vs. Chosen Hedge | K38: Why Rejected?
A42: SECTION 3 — INVESTMENT THESIS LOG
A43: Complete one thesis block per security. Thesis # must match column K in Section 1. Each thesis must: (1) identify the macro connection to Phase 1, (2) cite a verifiable data source, and (3) confirm IPS suitability for this client.
A44: Thesis #1
B45: Security (Ticker + Name)
B46: Asset Class / Sector
B47: Macro Connection
B48: Investment Rationale
B49: Data Source & Citation
B50: IPS Suitability
...

Sheet ISSUER CHECK
A1: BUS 331 — Issuer Reality Check
A2: Required inside Security Analysis and Selection — not a separate accounting unit
A4: DECISION RULE — Yield or recent return alone cannot support a recommendation. Evidence the issuer's financial health, operating outlook, and relevance to the client's mandate.
A5: APPLIES TO — Every direct bond or equity exposure, plus the most material relevant issuer or holding within each selected mutual fund or ETF.
A7: ROLE HANDOFF — Fixed-Income: credit review | Fund & ETF: look-through holdings/concentration | Client & Macro: scenario impact | Portfolio & Risk: allocation, diversification, stress, and monitoring
A9: EXPOSURE & EVIDENCE | I9: ISSUER HEALTH & OUTLOOK | R9: RISK, CLIENT FIT & ALLOCATION | V9: REVIEW
A10: Client | B10: Exposure Type | C10: Security / Fund | D10: Issuer / Look-Through Holding | E10: Portfolio Weight | F10: Primary Owner | G10: Source / URL | H10: As-of Date | I10: Business Model | J10: Revenue Drivers | K10: Industry / Macro Sensitivity | L10: Revenue Trend | M10: Margin Trend | N10: Cash-Flow Trend | O10: Liquidity | P10: Leverage | Q10: Interest Coverage / Debt Maturities (if relevant) | R10: Issuer-Specific Risk | S10: Client-Fit Conclusion | T10: Allocation Implication | U10: Monitoring Trigger | V10: Peer Reviewer | W10: Status
A24: COMPLETION STANDARD — Concise and cited. Show consistent financial periods, label missing information, and end with a client-fit and allocation conclusion. A second team member reviews each row before committee approval.

Sheet EVIDENCE LOG
A1: BUS 331 — FactSet Research and Evidence Log
A2: Required licensed-source record — document the retrieval, interpret the evidence, and explain its effect on the recommendation
A4: BOUNDARY — Use licensed FactSet access for course research. Submit final work and required licensed-source evidence privately through Canvas. Do not place FactSet captures, exports, credentials, completed proprietary data files, or student work in the public repository.
A5: NAVIGATION NOTE — FactSet layouts, labels, and entitlements can differ. Follow course demonstrations and current FactSet support; this log defines evidence requirements, not a click path.
A8: Client | B8: Workstream | C8: Security / Issuer / Fund / Benchmark / Input | D8: Research Question or Claim Tested | E8: FactSet Data / Research Retrieved | F8: Relevant Metrics & Units | G8: Entity / Security Identifier | H8: Source / Screen / Document Reference | I8: Data As-of Period | J8: Retrieval Date | K8: Interpretation & Limitations | L8: Result | M8: Effect on Recommendation / Portfolio Input | N8: Canvas Submission Item / Evidence-File Reference | O8: Analyst Owner | P8: Peer Reviewer | Q8: Status
